Workbook
Name __xlnm.Print_Area: #REF!
Name Add_Budget_Selection: #REF!
Name Analysis_End_Date: #REF!
Name Analysis_End_Month: #REF!
Name Analysis_Length_Months: #REF!
Name Analysis_Length_Years: #REF!
Name Analysis_Start_Date: #REF!
Name Analysis_Start_Month: #REF!
Name Category_1: #REF!
Name Category_2: #REF!
Name Category_3: #REF!
Name Category_4: #REF!
Name Category_5: #REF!
Name Category_6: #REF!
Name Category_7: #REF!
Name Const_End_Date: #REF!
Name Const_End_Month: #REF!
Name Const_Start_Date: #REF!
Name Construction_Int_Rate: #REF!
Name Construction_Length: #REF!
Name Construction_Loan_Amount: #REF!
Name Construction_Module_On?: #REF!
Name Equity_Contribution: #REF!
Name Equity_Share_LP: #REF!
Name Equity_Share_LP_Monthly: #REF!
Name Equity_Share_Sponsor: #REF!
Name Equity_Share_Sponsor_Monthly: #REF!
Name Financing_Module_On: #REF!
Name GL_Module_On?: #REF!
Name Ground_Lease_Years_Remaining: #REF!
Name Growth_Begin_Month: #REF!
Name Investment_Name: #REF!
Name Investment_Period_Months: #REF!
Name IRR_Type: #REF!
Name Jr_Funding_Month: #REF!
Name Label_SF_M2: #REF!
Name Label_Unit_Type: #REF!
Name Label_Unit_Type_Singular: #REF!
Name List_Location: OFFSET(#REF!,0,0,93-COUNTIF(#REF!,""),1)
Name List_Property_Type: OFFSET(#REF!,0,0,1,10-COUNTIF(#REF!,""))
Name Location: #REF!
Name LTC_Actual: #REF!
Name Manager_Salary_Per_Month: #N/A
Name Managersalaryper: #N/A
Name Managersalarypermonth: #N/A
Name MF_1st_Stab_Month: #REF!
Name MF_Module_On: #REF!
Name MF_Units: #REF!
Name MF_Untrended?: #REF!
Name NRA: #REF!
Name Operation_Period_Months: #REF!
Name Operations_Begin_Date: #REF!
Name Operations_Begin_Month: #REF!
Name ORI_1st_Stab_Month: #REF!
Name ORI_Module_On: #REF!
Name ORI_Untrended?: #REF!
Name Per_Unit_Type: #REF!
Name Perm_Debt_Funding: #REF!
Name PermDebt_Funding_Date: #REF!
Name PermDebt_Funding_Month: MAX(#REF!,1)

Sheet Cover Page
N3: =+Dashboard!$E$10 -> […]
N4: =+Dashboard!$E$12&", "&Dashboard!$E$13 -> […], […]
N6: =TODAY() -> 46065

Sheet Dashboard
C3: Model Dashboard
C5: Assumptions
C7: Transaction Summary | G7: Sources & Uses | L7: Operating Assumptions | Y7: Returns Summary
C9: Transaction Overview | G9: Sources | I9: $ | J9: % | L9: Broader Model General Assumptions | R9: Utility Expenses | U9: Cost / Unit | V9: Year 1 Cost | Y9: Return Summary (Gross)
C10: Investment Name | E10: […] | G10: Total Debt | I10: =+D49 -> 2795000 | J10: =+I10/$I$12 -> 0.60524036 | L10: Vacancy | P10: 0.05 | R10: Electric | U10: =+V10/$E$16 -> 0 | Y10: Scenario 1
C11: Address | E11: […] | G11: Total Equity | I11: =+I12-I10 -> 1823000 | J11: =+I11/$I$12 -> 0.39475964 | L11: Rent Increase | P11: 0.03 | R11: Electric - Vacant | U11: =+V11/$E$16 -> 0 | AA11: Unlevered | AB11: Levered
C12: City | E12: […] | G12: Total Sources | I12: =+I17 -> 4618000 | J12: =SUM(J10:J11) -> 1 | L12: Utility Expense | P12: 0.03 | R12: Water & Sewer | U12: =+V12/$E$16 -> 0 | Y12: IRR | AA12: =+'Scenario 1'!$E$122 -> 0.11402295 | AB12: =+'Scenario 1'!$E$134 -> 0.13796015
C13: State | E13: […] | L13: Move Outs Per Year | P13: =+O13/E16 -> 0 | R13: Gas | U13: =+V13/$E$16 -> 0 | Y13: MOIC | AA13: =+'Scenario 1'!$E$123 -> 1.6264055 | AB13: =+'Scenario 1'!$E$135 -> 1.80481
C14: Zipcode | E14: […] | G14: Uses | I14: $ | J14: % | L14: Other Income | P14: 0.025 | R14: Cable | U14: =+V14/$E$16 -> 0 | Y14: Profit ($m) | AA14: =+('Scenario 1'!$J$119+'Scenario 1'!$E$119)/1000000 -> 1.4685247 | AB14: =+('Scenario 1'!$J$131+'Scenario 1'!$E$131)/1000000 -> 0.96884966
C15: Property Type | E15: […] | G15: Purchase Price | I15: =+E32 -> 4300000 | J15: =+I15/$I$17 -> 0.93113902 | L15: Inflation Increase | P15: 0.03 | R15: Trash/Garbage | U15: =+V15/$E$16 -> 0
C16: Units | E16: 72 | G16: Closing and Financing Costs | I16: =+SUM(E34:E40) -> 318000 | J16: =+I16/$I$17 -> 0.068860979 | L16: Insurance Increase | P16: 0.2 | Y16: Return Summary (Gross)
C17: Buildings | E17: […] | G17: Total Uses | I17: =SUM(I15:I16) -> 4618000 | J17: =SUM(J15:J16) -> 1 | Y17: Scenario 2
C18: Year Built | E18: […] | AA18: Unlevered | AB18: Levered
C19: Initial TCCP End Date | E19: […] | G19: Deal Scenario Summary and Stats | L19: Admin Expenses | N19: Growth Rate | O19: Cost / Unit | P19: Yr. 1 Cost | R19: Operating & Maint. | U19: Cost / Unit | V19: Year 1 Cost | Y19: IRR | AA19: =+'Scenario 2'!$E$122 -> 0.1500536 | AB19: =+'Scenario 2'!$E$134 -> 0.21238056
C20: Final Year of LIHTC Restrictions | E20: […] | G20: Unit Occupancy Statistics | I20: # of Units | J20: % | L20: Bad Debt Expense | N20: 0.015 | O20: =+P20/E16 -> 0 | R20: In-House R&M (per unit) | U20: 0 | V20: =+U20*E16 -> 0 | Y20: MOIC | AA20: =+'Scenario 2'!$E$123 -> 1.8714613 | AB20: =+'Scenario 2'!$E$135 -> 2.3828351
C21: Total Rentable SF | E21: =+'Rent Roll'!N4 -> 59002 | G21: Occupied Units | I21: ='Rent Roll'!C4 -> 68 | J21: =+J23-J22 -> 0.94444444 | L21: Replacement Reserves (cost per unit) | N21: 0 | O21: 300 | P21: =+O21*E16 -> 21600 | R21: Turnover (assumed cost per move out) | U21: 700 | V21: =+U21*O13 -> 0 | Y21: Profit ($m) | AA21: =+('Scenario 2'!$J$119+'Scenario 2'!$E$119)/1000000 -> 2.3369282 | AB21: =+('Scenario 2'!$J$131+'Scenario 2'!$E$131)/1000000 -> 1.8372532
C22: SF / Unit | E22: =+E21/E16 -> 819.47222 | G22: Vacant Units | I22: ='Rent Roll'!C5 -> 4 | J22: =I22/I23 -> 0.055555556 | L22: Compliance Fee | N22: 0 | O22: 0 | P22: 0 | R22: Supplies | U22: =+V22/$E$16 -> 180 | V22: =+(V23*P13)+(V24*E16)*V25 -> 12960
C23: Total Cost / SF | E23: =+I17/E21 -> 78.268533 | G23: Total Units | I23: =+E16 -> 72 | J23: =+I23/$I$23 -> 1 | L23: COVID Late fee (years 1-2) | P23: 0 | R23: Turnover Supplies / Year | V23: 3600 | Y23: Return Summary (Gross)
C24: Total Cost / Unit | E24: =+E22*E23 -> 64138.889 | R24: Supplies / Unit / Year | V24: 150 | Y24: Scenario 3
C25: TTM Occupancy (insert month / year) | E25: […] | G25: ='Rent Roll'!$J$3 -> AMI / S8 Breakdown | I25: # of Units | J25: % | L25: Employee Work Schedule Assumptions | R25: Supplies Overage Multiplier | V25: 1.2 | AA25: Unlevered | AB25: Levered
C26: TTM NOI (insert month / year) | E26: […] | G26: ='Rent Roll'!J4 -> 40% AMI | I26: ='Rent Roll'!K4 -> 2 | J26: =+I26/$I$31 -> 0.027777778 | L26: Hours per Week | P26: 40 | R26: Appliance/Electrical | U26: 175 | V26: =+(E16/6)*U26 -> 2100 | Y26: IRR | AA26: =+'Scenario 3'!$E$122 -> 0.16185258 | AB26: =+'Scenario 3'!$E$134 -> 0.23548185
G27: ='Rent Roll'!J5 -> 50% AMI | I27: ='Rent Roll'!K5 -> 9 | J27: =+I27/$I$31 -> 0.125 | L27: Weeks per Year | P27: 52 | R27: HVAC & Plumbing | U27: =+V27/$E$16 -> 0 | V27: 0 | Y27: MOIC | AA27: =+'Scenario 3'!$E$123 -> 1.9569722 | AB27: =+'Scenario 3'!$E$135 -> 2.5845341
C28: Transaction Assumptions and Statistics | E28: Total Cost | G28: ='Rent Roll'!J6 -> 60% AMI | I28: ='Rent Roll'!K6 -> 27 | J28: =+I28/$I$31 -> 0.375 | R28: Rent Concessions | U28: 0 | V28: =+U28*$E$16 -> 0 | Y28: Profit ($m) | AA28: =+('Scenario 3'!$J$119+'Scenario 3'!$E$119)/1000000 -> 2.6399532 | AB28: =+('Scenario 3'!$J$131+'Scenario 3'!$E$131)/1000000 -> 2.1402782
C29: Asking Price | E29: 4300000 | G29: ='Rent Roll'!J7 -> Market | I29: ='Rent Roll'!K7 -> 2 | J29: =+I29/$I$31 -> 0.027777778
C30: Asking Cap Rate (Year 0) | E30: =+'Scenario 0'!E89/Dashboard!E29 -> 0.35488651 | G30: ='Rent Roll'!J8 -> S8 Voucher | I30: ='Rent Roll'!K8 -> 32 | J30: =+I30/$I$31 -> 0.44444444 | L30: Employee Work Schedule Expenses | M30: Include? | N30: Hourly | O30: Monthly | P30: Yearly | R30: Contract Expenses | V30: Total $
C31: Cost Per Unit (Asking Price) | E31: =+E29/E16 -> 59722.222 | G31: Total Units | I31: =SUM(I26:I30) -> 72 | J31: =SUM(J26:J30) -> 1 | L31: Regional Manager Salary | M31: Yes | N31: =+P31/P26/P27 -> 6.9230769 | O31: 1200 | P31: =++IF(M31="Yes",O31*12,0) -> 14400 | R31: Landscaping/Grounds Contract
C32: Purchase Price | E32: =E29 -> 4300000 | L32: Property Manager Salary | M32: Yes | N32: 27 | O32: =+P32/12 -> 4680 | P32: =+IF(M32="Yes",N32*$P$26*$P$27,0) -> 56160 | R32: Fire & Safety System
C33: Cost Per Unit (Purchase Price) | E33: =+E32/$E$16 -> 59722.222 | G33: ='Rent Roll'!$F$3 -> Unit Types | I33: # of Units | J33: % | L33: Assistant Property Manager Salary | M33: No | N33: 20 | O33: =+P33/12 -> 0 | P33: =+IF(M33="Yes",N33*$P$26*$P$27,0) -> 0 | R33: Security
C34: Closing Costs | D34: 0.02 | E34: =+$D$34*$E$32 -> 86000 | G34: ='Rent Roll'!F4 -> 1x1 | I34: ='Rent Roll'!G4 -> 6 | J34: =+I34/$I$31 -> 0.083333333 | L34: Commissions / Bonuses | M34: No | N34: 0 | O34: =+P34/12 -> 0 | P34: =+IF(M34="Yes",N34*$P$26*$P$27,0) -> 0 | R34: Pest Control
C35: Broker Fees | D35: 0 | E35: =+E32*D35 -> 0 | G35: ='Rent Roll'!F5 -> 2x1.5 | I35: ='Rent Roll'!G5 -> 6 | J35: =+I35/$I$31 -> 0.083333333 | L35: Maintenance Salary | M35: Yes | N35: 27 | O35: =+P35/12 -> 4680 | P35: =+IF(M35="Yes",N35*$P$26*$P$27,0) -> 56160 | R35: Misc. Contracts
C36: Rehabilitation Costs | D36: 1000 | E36: =+D36*E16 -> 72000 | G36: ='Rent Roll'!F6 -> 2x2 | I36: ='Rent Roll'!G6 -> 3 | J36: =+I36/$I$31 -> 0.041666667 | L36: Maintenance Assistant Salary | M36: No | N36: 0 | O36: =+P36/12 -> 0 | P36: =+IF(M36="Yes",N36*$P$26*$P$27,0) -> 0 | R36: Elevator Costs
C37: Legal Fees | E37: 35000 | G37: ='Rent Roll'!F7 -> 2x2 (TH) | I37: ='Rent Roll'!G7 -> 19 | J37: =+I37/$I$31 -> 0.26388889 | L37: Labor Increase % | N37: 0.03 | R37: Snow
C38: Developer Fees | E38: 100000 | G38: ='Rent Roll'!F8 -> 2x1.5-2x2 | I38: ='Rent Roll'!G8 -> 18 | J38: =+I38/$I$31 -> 0.25 | R38: Misc. Operating & Maint.
C39: Due Diligence Fees | E39: 25000 | G39: ='Rent Roll'!F9 -> 3x2 (TH) | I39: ='Rent Roll'!G9 -> 20 | J39: =+I39/$I$31 -> 0.27777778
C40: Taxes / Title Insurance | E40: 0 | G40: Total Units | I40: =SUM(I34:I39) -> 72 | J40: =SUM(J34:J39) -> 1 | L40: Admin Expenses | O40: Cost / Unit | P40: Yr. 1 Cost | R40: Real Estate Taxes and Insurance | V40: Total $
L41: Management Fee (% of Net Rental Income) | P41: 0.05 | R41: Market Value | V41: =+E32*U41 -> 0
C42: GP / LP Initial Equity Investment | G42: Additional Unit Statistics | L42: Legal Expense | O42: =+P42/$E$16 -> 83.333333 | P42: 6000 | R42: Less: Taxable Value | V42: =+V41*U42 -> 0
C43: GP Equity Investment | D43: 0.1 | E43: =+(I17-I10)*D43 -> 182300 | G43: Average Gross Rent | J43: ='Rent Roll'!O4 -> 775.11111 | L43: Office Expense (Per Unit) | O43: 150 | P43: =+O43*$E$16 -> 10800 | R43: RE Taxes | T43: Prop. Tax Rate (Milage) -> | V43: =+V42*U43/10 -> 0
C44: LP Equity Investment | D44: =1-D43 -> 0.9 | E44: =+(I17-I10)*D44 -> 1640700 | G44: Average Effective Rent | J44: ='Rent Roll'!P4 -> 687.125 | L44: Travel Cost | O44: =+P44/$E$16 -> 83.333333 | P44: 6000 | R44: Stormwater Fees
G45: % of Gross Rent | J45: =+J44/J43 -> 0.88648581 | L45: Audit Expense | O45: =+P45/$E$16 -> 90.277778 | P45: 6500 | R45: Less Discounts | V45: =+V43*U45 -> 0
...

Sheet Models -->

Sheet Scenario 0
C1: Underwriting Model Scenario 0
D3: Year | E3: 2024 | F3: =+E3+1 -> 2025 | G3: =+F3+1 -> 2026 | H3: =+G3+1 -> 2027 | I3: =+H3+1 -> 2028 | J3: =+I3+1 -> 2029 | K3: =+J3+1 -> 2030 | L3: =+K3+1 -> 2031 | M3: =+L3+1 -> 2032 | ... O3: =+N3+1 -> 2034
C4: Scenario 0 (No Change to Asset)
C6: Income Statement | E6: T12 | F6: 1 | G6: =+F6+1 -> 2 | H6: =+G6+1 -> 3 | I6: =+H6+1 -> 4 | J6: =+I6+1 -> 5 | K6: =+J6+1 -> 6 | L6: =+K6+1 -> 7 | M6: =+L6+1 -> 8 | N6: =+M6+1 -> 9 | O6: =+N6+1 -> 10
A7: GPI | C7: Gross Potential Income | E7: =1561954 -> 1561954 | F7: ='Unit Mix'!N26 -> 593676 | G7: ='Unit Mix'!N49 -> 611486.28 | H7: ='Unit Mix'!N72 -> 629830.87 | I7: ='Unit Mix'!N95 -> 648725.79 | J7: =+'Unit Mix'!N118 -> 668187.57 | K7: =+'Unit Mix'!N141 -> 688233.2 | L7: =+'Unit Mix'!N164 -> 708880.19 | M7: =+'Unit Mix'!N187 -> 730146.6 | N7: =+'Unit Mix'!N210 -> 752050.99 | O7: ='Unit Mix'!N233 -> 774612.52
A8: VC | C8: Vacancy Factor | D8: =+Dashboard!$P$10 -> 0.05 | E8: 48058 | F8: =+F7*$D$8 -> 29683.8 | G8: =+G7*$D$8 -> 30574.314 | H8: =+H7*$D$8 -> 31491.543 | I8: =+I7*$D$8 -> 32436.29 | J8: =+J7*$D$8 -> 33409.378 | K8: =+K7*$D$8 -> 34411.66 | L8: =+L7*$D$8 -> 35444.01 | M8: =+M7*$D$8 -> 36507.33 | ... O8: =+O7*$D$8 -> 38730.626
C9: Net Rental Income | E9: =+E7-E8 -> 1513896 | F9: =+F7-F8 -> 563992.2 | G9: =+G7-G8 -> 580911.97 | H9: =+H7-H8 -> 598339.32 | I9: =+I7-I8 -> 616289.5 | J9: =+J7-J8 -> 634778.19 | K9: =+K7-K8 -> 653821.54 | L9: =+L7-L8 -> 673436.18 | ... O9: =+O7-O8 -> 735881.9
A11: OI | C11: Laundry and Other Income | D11: =+Dashboard!$P$14 -> 0.025 | E11: 33716 | F11: =+Dashboard!$O$14 -> 0 | G11: =+F11*(1+$D11) -> 0 | H11: =+G11*(1+$D11) -> 0 | I11: =+H11*(1+$D11) -> 0 | J11: =+I11*(1+$D11) -> 0 | K11: =+J11*(1+$D11) -> 0 | L11: =+K11*(1+$D11) -> 0 | M11: =+L11*(1+$D11) -> 0 | N11: =+M11*(1+$D11) -> 0 | O11: =+N11*(1+$D11) -> 0
C12: Total Gross Income | E12: =+SUM(E9:E11) -> 1547612 | F12: =+SUM(F9:F11) -> 563992.2 | G12: =+SUM(G9:G11) -> 580911.97 | H12: =+SUM(H9:H11) -> 598339.32 | I12: =+SUM(I9:I11) -> 616289.5 | J12: =+SUM(J9:J11) -> 634778.19 | K12: =+SUM(K9:K11) -> 653821.54 | L12: =+SUM(L9:L11) -> 673436.18 | ... O12: =+SUM(O9:O11) -> 735881.9
C13: Gross Income Growth | E13: -- | F13: =+F12/E12-1 -> -0.63557261 | G13: =+G12/F12-1 -> 0.03 | H13: =+H12/G12-1 -> 0.03 | I13: =+I12/H12-1 -> 0.03 | J13: =+J12/I12-1 -> 0.03 | K13: =+K12/J12-1 -> 0.03 | L13: =+L12/K12-1 -> 0.03 | M13: =+M12/L12-1 -> 0.03 | ... O13: =+O12/N12-1 -> 0.03
C15: Opertating Expenses
A17: BAD | C17: Bad Debt | D17: =+Dashboard!$N$20 -> 0.015 | F17: =+Dashboard!P20 -> 0 | G17: =+F17*(1+$D17) -> 0 | H17: =+G17*(1+$D17) -> 0 | I17: =+H17*(1+$D17) -> 0 | J17: =+I17*(1+$D17) -> 0 | K17: =+J17*(1+$D17) -> 0 | L17: =+K17*(1+$D17) -> 0 | M17: =+L17*(1+$D17) -> 0 | N17: =+M17*(1+$D17) -> 0 | O17: =+N17*(1+$D17) -> 0
C18: Bad Debt | E18: =+SUM(E17) -> 0 | F18: =+SUM(F17) -> 0 | G18: =+SUM(G17) -> 0 | H18: =+SUM(H17) -> 0 | I18: =+SUM(I17) -> 0 | J18: =+SUM(J17) -> 0 | K18: =+SUM(K17) -> 0 | L18: =+SUM(L17) -> 0 | ... O18: =+SUM(O17) -> 0
A20: RES | C20: Replacement Reserves | D20: =+Dashboard!$N$21 -> 0 | E20: =+F20 -> 21600 | F20: =+Dashboard!P21 -> 21600 | G20: =+F20*(1+$D20) -> 21600 | H20: =+G20*(1+$D20) -> 21600 | I20: =+H20*(1+$D20) -> 21600 | J20: =+I20*(1+$D20) -> 21600 | K20: =+J20*(1+$D20) -> 21600 | L20: =+K20*(1+$D20) -> 21600 | M20: =+L20*(1+$D20) -> 21600 | N20: =+M20*(1+$D20) -> 21600 | O20: =+N20*(1+$D20) -> 21600
A21: COM | C21: Compliance Fee | D21: =+Dashboard!$N$22 -> 0 | E21: 0 | F21: =+Dashboard!P22 -> 0 | G21: =+F21*(1+$D21) -> 0 | H21: =+G21*(1+$D21) -> 0 | I21: =+H21*(1+$D21) -> 0 | J21: =+I21*(1+$D21) -> 0 | K21: =+J21*(1+$D21) -> 0 | L21: =+K21*(1+$D21) -> 0 | M21: =+L21*(1+$D21) -> 0 | N21: =+M21*(1+$D21) -> 0 | O21: =+N21*(1+$D21) -> 0
C22: Total Replacement Reserves | E22: =SUM(E20:E21) -> 21600 | F22: =SUM(F20:F21) -> 21600 | G22: =SUM(G20:G21) -> 21600 | H22: =SUM(H20:H21) -> 21600 | I22: =SUM(I20:I21) -> 21600 | J22: =SUM(J20:J21) -> 21600 | K22: =SUM(K20:K21) -> 21600 | L22: =SUM(L20:L21) -> 21600 | ... O22: =SUM(O20:O21) -> 21600
A24: REG | C24: Regional Manager Salary | D24: =+Dashboard!$N$37 -> 0.03 | F24: =+Dashboard!P31 -> 14400 | G24: =+F24*(1+$D24) -> 14832 | H24: =+G24*(1+$D24) -> 15276.96 | I24: =+H24*(1+$D24) -> 15735.269 | J24: =+I24*(1+$D24) -> 16207.327 | K24: =+J24*(1+$D24) -> 16693.547 | L24: =+K24*(1+$D24) -> 17194.353 | M24: =+L24*(1+$D24) -> 17710.184 | N24: =+M24*(1+$D24) -> 18241.489 | O24: =+N24*(1+$D24) -> 18788.734
A25: MAN | C25: Property Manager Salary | D25: =+Dashboard!$N$37 -> 0.03 | F25: =+Dashboard!P32 -> 56160 | G25: =+F25*(1+$D25) -> 57844.8 | H25: =+G25*(1+$D25) -> 59580.144 | I25: =+H25*(1+$D25) -> 61367.548 | J25: =+I25*(1+$D25) -> 63208.575 | K25: =+J25*(1+$D25) -> 65104.832 | L25: =+K25*(1+$D25) -> 67057.977 | M25: =+L25*(1+$D25) -> 69069.716 | N25: =+M25*(1+$D25) -> 71141.808 | O25: =+N25*(1+$D25) -> 73276.062
A26: ASS | C26: Assistant Manager (over 160 units) | D26: =+Dashboard!$N$37 -> 0.03 | F26: =+Dashboard!P33 -> 0 | G26: =+F26*(1+$D26) -> 0 | H26: =+G26*(1+$D26) -> 0 | I26: =+H26*(1+$D26) -> 0 | J26: =+I26*(1+$D26) -> 0 | K26: =+J26*(1+$D26) -> 0 | L26: =+K26*(1+$D26) -> 0 | M26: =+L26*(1+$D26) -> 0 | N26: =+M26*(1+$D26) -> 0 | O26: =+N26*(1+$D26) -> 0
A27: PAY | C27: Commissions/Bonuses | D27: =+Dashboard!$N$37 -> 0.03 | F27: =+Dashboard!P34 -> 0 | G27: =+F27*(1+$D27) -> 0 | H27: =+G27*(1+$D27) -> 0 | I27: =+H27*(1+$D27) -> 0 | J27: =+I27*(1+$D27) -> 0 | K27: =+J27*(1+$D27) -> 0 | L27: =+K27*(1+$D27) -> 0 | M27: =+L27*(1+$D27) -> 0 | N27: =+M27*(1+$D27) -> 0 | O27: =+N27*(1+$D27) -> 0
A28: MAIT | C28: Maintenance Salary | D28: =+Dashboard!$N$37 -> 0.03 | F28: =+Dashboard!P35+Dashboard!P36 -> 56160 | G28: =+F28*(1+$D28) -> 57844.8 | H28: =+G28*(1+$D28) -> 59580.144 | I28: =+H28*(1+$D28) -> 61367.548 | J28: =+I28*(1+$D28) -> 63208.575 | K28: =+J28*(1+$D28) -> 65104.832 | L28: =+K28*(1+$D28) -> 67057.977 | M28: =+L28*(1+$D28) -> 69069.716 | N28: =+M28*(1+$D28) -> 71141.808 | O28: =+N28*(1+$D28) -> 73276.062
C29: Payroll | E29: =SUM(E24:E28) -> 0 | F29: =SUM(F24:F28) -> 126720 | G29: =SUM(G24:G28) -> 130521.6 | H29: =SUM(H24:H28) -> 134437.25 | I29: =SUM(I24:I28) -> 138470.37 | J29: =SUM(J24:J28) -> 142624.48 | K29: =SUM(K24:K28) -> 146903.21 | L29: =SUM(L24:L28) -> 151310.31 | ... O29: =SUM(O24:O28) -> 165340.86
A31: MGMT | C31: Management Fee | D31: =+Dashboard!$P$41 -> 0.05 | F31: =+F9*$D$31 -> 28199.61 | G31: =+G9*$D$31 -> 29045.598 | H31: =+H9*$D$31 -> 29916.966 | I31: =+I9*$D$31 -> 30814.475 | J31: =+J9*$D$31 -> 31738.909 | K31: =+K9*$D$31 -> 32691.077 | L31: =+L9*$D$31 -> 33671.809 | M31: =+M9*$D$31 -> 34681.963 | ... O31: =+O9*$D$31 -> 36794.095
A32: LEGAL | C32: Legal Expense | D32: =+Dashboard!$P$15 -> 0.03 | F32: =Dashboard!P42 -> 6000 | G32: =+F32*(1+$D32) -> 6180 | H32: =+G32*(1+$D32) -> 6365.4 | I32: =+H32*(1+$D32) -> 6556.362 | J32: =+I32*(1+$D32) -> 6753.0529 | K32: =+J32*(1+$D32) -> 6955.6444 | L32: =+K32*(1+$D32) -> 7164.3138 | M32: =+L32*(1+$D32) -> 7379.2432 | N32: =+M32*(1+$D32) -> 7600.6205 | O32: =+N32*(1+$D32) -> 7828.6391
A33: OFF | C33: Office Expense | D33: =+Dashboard!$P$15 -> 0.03 | F33: =Dashboard!P43 -> 10800 | G33: =+F33*(1+$D33) -> 11124 | H33: =+G33*(1+$D33) -> 11457.72 | I33: =+H33*(1+$D33) -> 11801.452 | J33: =+I33*(1+$D33) -> 12155.495 | K33: =+J33*(1+$D33) -> 12520.16 | L33: =+K33*(1+$D33) -> 12895.765 | M33: =+L33*(1+$D33) -> 13282.638 | N33: =+M33*(1+$D33) -> 13681.117 | O33: =+N33*(1+$D33) -> 14091.55
A34: TRAVEL | C34: Travel Cost | D34: =+Dashboard!$P$15 -> 0.03 | F34: =Dashboard!P44 -> 6000 | G34: =+F34*(1+$D34) -> 6180 | H34: =+G34*(1+$D34) -> 6365.4 | I34: =+H34*(1+$D34) -> 6556.362 | J34: =+I34*(1+$D34) -> 6753.0529 | K34: =+J34*(1+$D34) -> 6955.6444 | L34: =+K34*(1+$D34) -> 7164.3138 | M34: =+L34*(1+$D34) -> 7379.2432 | N34: =+M34*(1+$D34) -> 7600.6205 | O34: =+N34*(1+$D34) -> 7828.6391
A35: AUD | C35: Audit Expense | D35: =+Dashboard!$P$15 -> 0.03 | F35: =Dashboard!P45 -> 6500 | G35: =+F35*(1+$D35) -> 6695 | H35: =+G35*(1+$D35) -> 6895.85 | I35: =+H35*(1+$D35) -> 7102.7255 | J35: =+I35*(1+$D35) -> 7315.8073 | K35: =+J35*(1+$D35) -> 7535.2815 | L35: =+K35*(1+$D35) -> 7761.3399 | M35: =+L35*(1+$D35) -> 7994.1801 | N35: =+M35*(1+$D35) -> 8234.0055 | O35: =+N35*(1+$D35) -> 8481.0257
A36: ADV | C36: Advertising | D36: =+Dashboard!$P$15 -> 0.03 | F36: =Dashboard!P46 -> 0 | G36: =+F36*(1+$D36) -> 0 | H36: =+G36*(1+$D36) -> 0 | I36: =+H36*(1+$D36) -> 0 | J36: =+I36*(1+$D36) -> 0 | K36: =+J36*(1+$D36) -> 0 | L36: =+K36*(1+$D36) -> 0 | M36: =+L36*(1+$D36) -> 0 | N36: =+M36*(1+$D36) -> 0 | O36: =+N36*(1+$D36) -> 0
A37: TRAIN | C37: Training Charge | D37: =+Dashboard!$P$15 -> 0.03 | F37: =Dashboard!P47 -> 0 | G37: =+F37*(1+$D37) -> 0 | H37: =+G37*(1+$D37) -> 0 | I37: =+H37*(1+$D37) -> 0 | J37: =+I37*(1+$D37) -> 0 | K37: =+J37*(1+$D37) -> 0 | L37: =+K37*(1+$D37) -> 0 | M37: =+L37*(1+$D37) -> 0 | N37: =+M37*(1+$D37) -> 0 | O37: =+N37*(1+$D37) -> 0
A38: BANK | C38: Bank Charges | D38: =+Dashboard!$P$15 -> 0.03 | F38: =Dashboard!P48 -> 0 | G38: =+F38*(1+$D38) -> 0 | H38: =+G38*(1+$D38) -> 0 | I38: =+H38*(1+$D38) -> 0 | J38: =+I38*(1+$D38) -> 0 | K38: =+J38*(1+$D38) -> 0 | L38: =+K38*(1+$D38) -> 0 | M38: =+L38*(1+$D38) -> 0 | N38: =+M38*(1+$D38) -> 0 | O38: =+N38*(1+$D38) -> 0
A39: BOOK | C39: Bookkeeping | D39: =+Dashboard!$P$15 -> 0.03 | F39: =Dashboard!P49 -> 2000 | G39: =+F39*(1+$D39) -> 2060 | H39: =+G39*(1+$D39) -> 2121.8 | I39: =+H39*(1+$D39) -> 2185.454 | J39: =+I39*(1+$D39) -> 2251.0176 | K39: =+J39*(1+$D39) -> 2318.5481 | L39: =+K39*(1+$D39) -> 2388.1046 | M39: =+L39*(1+$D39) -> 2459.7477 | N39: =+M39*(1+$D39) -> 2533.5402 | O39: =+N39*(1+$D39) -> 2609.5464
A40: PAYSERV | C40: Payroll Service | D40: =+Dashboard!$P$15 -> 0.03 | F40: =Dashboard!P50 -> 0 | G40: =+F40*(1+$D40) -> 0 | H40: =+G40*(1+$D40) -> 0 | I40: =+H40*(1+$D40) -> 0 | J40: =+I40*(1+$D40) -> 0 | K40: =+J40*(1+$D40) -> 0 | L40: =+K40*(1+$D40) -> 0 | M40: =+L40*(1+$D40) -> 0 | N40: =+M40*(1+$D40) -> 0 | O40: =+N40*(1+$D40) -> 0
A41: UNIT | C41: Manager Unit | D41: =+Dashboard!$P$15 -> 0.03 | F41: =Dashboard!P51 -> 0 | G41: =+F41*(1+$D41) -> 0 | H41: =+G41*(1+$D41) -> 0 | I41: =+H41*(1+$D41) -> 0 | J41: =+I41*(1+$D41) -> 0 | K41: =+J41*(1+$D41) -> 0 | L41: =+K41*(1+$D41) -> 0 | M41: =+L41*(1+$D41) -> 0 | N41: =+M41*(1+$D41) -> 0 | O41: =+N41*(1+$D41) -> 0
A42: MISCAD | C42: Misc. Admin Expenses | D42: =+Dashboard!$P$15 -> 0.03 | E42: 0 | F42: =Dashboard!P52 -> 0 | G42: =+F42*(1+$D42) -> 0 | H42: =+G42*(1+$D42) -> 0 | I42: =+H42*(1+$D42) -> 0 | J42: =+I42*(1+$D42) -> 0 | K42: =+J42*(1+$D42) -> 0 | L42: =+K42*(1+$D42) -> 0 | M42: =+L42*(1+$D42) -> 0 | N42: =+M42*(1+$D42) -> 0 | O42: =+N42*(1+$D42) -> 0
C43: Admin Expenses | E43: =SUM(E31:E42) -> 0 | F43: =SUM(F31:F42) -> 59499.61 | G43: =SUM(G31:G42) -> 61284.598 | H43: =SUM(H31:H42) -> 63123.136 | I43: =SUM(I31:I42) -> 65016.83 | J43: =SUM(J31:J42) -> 66967.335 | K43: =SUM(K31:K42) -> 68976.355 | L43: =SUM(L31:L42) -> 71045.646 | ... O43: =SUM(O31:O42) -> 77633.496
A45: ELEC | C45: Electric | D45: =+Dashboard!$P$15 -> 0.03 | F45: =+Dashboard!V10 -> 0 | G45: =+F45*(1+$D45) -> 0 | H45: =+G45*(1+$D45) -> 0 | I45: =+H45*(1+$D45) -> 0 | J45: =+I45*(1+$D45) -> 0 | K45: =+J45*(1+$D45) -> 0 | L45: =+K45*(1+$D45) -> 0 | M45: =+L45*(1+$D45) -> 0 | N45: =+M45*(1+$D45) -> 0 | O45: =+N45*(1+$D45) -> 0
A46: VAC | C46: Electric - Vacant | D46: =+Dashboard!$P$15 -> 0.03 | F46: =+Dashboard!V11 -> 0 | G46: =+F46*(1+$D46) -> 0 | H46: =+G46*(1+$D46) -> 0 | I46: =+H46*(1+$D46) -> 0 | J46: =+I46*(1+$D46) -> 0 | K46: =+J46*(1+$D46) -> 0 | L46: =+K46*(1+$D46) -> 0 | M46: =+L46*(1+$D46) -> 0 | N46: =+M46*(1+$D46) -> 0 | O46: =+N46*(1+$D46) -> 0
A47: WS | C47: Water & Sewer | D47: =+Dashboard!$P$15 -> 0.03 | F47: =+Dashboard!V12 -> 0 | G47: =+F47*(1+$D47) -> 0 | H47: =+G47*(1+$D47) -> 0 | I47: =+H47*(1+$D47) -> 0 | J47: =+I47*(1+$D47) -> 0 | K47: =+J47*(1+$D47) -> 0 | L47: =+K47*(1+$D47) -> 0 | M47: =+L47*(1+$D47) -> 0 | N47: =+M47*(1+$D47) -> 0 | O47: =+N47*(1+$D47) -> 0
A48: GAS | C48: Gas | D48: =+Dashboard!$P$15 -> 0.03 | F48: =+Dashboard!V13 -> 0 | G48: =+F48*(1+$D48) -> 0 | H48: =+G48*(1+$D48) -> 0 | I48: =+H48*(1+$D48) -> 0 | J48: =+I48*(1+$D48) -> 0 | K48: =+J48*(1+$D48) -> 0 | L48: =+K48*(1+$D48) -> 0 | M48: =+L48*(1+$D48) -> 0 | N48: =+M48*(1+$D48) -> 0 | O48: =+N48*(1+$D48) -> 0
A49: CABLE | C49: Cable | D49: =+Dashboard!$P$15 -> 0.03 | F49: =+Dashboard!V14 -> 0 | G49: =+F49*(1+$D49) -> 0 | H49: =+G49*(1+$D49) -> 0 | I49: =+H49*(1+$D49) -> 0 | J49: =+I49*(1+$D49) -> 0 | K49: =+J49*(1+$D49) -> 0 | L49: =+K49*(1+$D49) -> 0 | M49: =+L49*(1+$D49) -> 0 | N49: =+M49*(1+$D49) -> 0 | O49: =+N49*(1+$D49) -> 0
...

Sheet Scenario 1
C1: Underwriting Model Scenario 1
D3: Year | E3: =+'Scenario 0'!E3 -> 2024 | F3: =+'Scenario 0'!F3 -> 2025 | G3: =+'Scenario 0'!G3 -> 2026 | H3: =+'Scenario 0'!H3 -> 2027 | I3: =+'Scenario 0'!I3 -> 2028 | J3: =+'Scenario 0'!J3 -> 2029 | K3: =+'Scenario 0'!K3 -> 2030 | L3: =+'Scenario 0'!L3 -> 2031 | ... O3: =+'Scenario 0'!O3 -> 2034
C4: ='Unit Mix'!$P$3 -> Scenario 1 ( Max Current Vouchers)
C6: Income Statement | E6: =+'Scenario 0'!E6 -> T12 | F6: =+'Scenario 0'!F6 -> 1 | G6: =+'Scenario 0'!G6 -> 2 | H6: =+'Scenario 0'!H6 -> 3 | I6: =+'Scenario 0'!I6 -> 4 | J6: =+'Scenario 0'!J6 -> 5 | K6: =+'Scenario 0'!K6 -> 6 | L6: =+'Scenario 0'!L6 -> 7 | ... O6: =+'Scenario 0'!O6 -> 10
C7: Gross Potential Income | E7: =+'Scenario 0'!$E$7 -> 1561954 | F7: =+'Unit Mix'!U26 -> 593676 | G7: =+'Unit Mix'!U49 -> 611486.28 | H7: =+'Unit Mix'!U72 -> 629830.87 | I7: =+'Unit Mix'!U95 -> 648725.79 | J7: =+'Unit Mix'!U118 -> 668187.57 | K7: =+'Unit Mix'!U141 -> 688233.2 | L7: =+'Unit Mix'!U164 -> 708880.19 | M7: =+'Unit Mix'!U187 -> 730146.6 | N7: =+'Unit Mix'!U210 -> 752050.99 | O7: =+'Unit Mix'!U233 -> 774612.52
C8: Vacancy Factor | D8: =+Dashboard!$P$10 -> 0.05 | E8: =+'Scenario 0'!$E$8 -> 48058 | F8: =+F7*$D$8 -> 29683.8 | G8: =+G7*$D$8 -> 30574.314 | H8: =+H7*$D$8 -> 31491.543 | I8: =+I7*$D$8 -> 32436.29 | J8: =+J7*$D$8 -> 33409.378 | K8: =+K7*$D$8 -> 34411.66 | L8: =+L7*$D$8 -> 35444.01 | M8: =+M7*$D$8 -> 36507.33 | ... O8: =+O7*$D$8 -> 38730.626
C9: Net Rental Income | E9: =+E7-E8 -> 1513896 | F9: =+F7-F8 -> 563992.2 | G9: =+G7-G8 -> 580911.97 | H9: =+H7-H8 -> 598339.32 | I9: =+I7-I8 -> 616289.5 | J9: =+J7-J8 -> 634778.19 | K9: =+K7-K8 -> 653821.54 | L9: =+L7-L8 -> 673436.18 | ... O9: =+O7-O8 -> 735881.9
C11: Laundry and Other Income | D11: =+Dashboard!$P$14 -> 0.025 | E11: =+'Scenario 0'!$E$11 -> 33716 | F11: =+Dashboard!$O$14 -> 0 | G11: =+F11*(1+$D11) -> 0 | H11: =+G11*(1+$D11) -> 0 | I11: =+H11*(1+$D11) -> 0 | J11: =+I11*(1+$D11) -> 0 | K11: =+J11*(1+$D11) -> 0 | L11: =+K11*(1+$D11) -> 0 | M11: =+L11*(1+$D11) -> 0 | N11: =+M11*(1+$D11) -> 0 | O11: =+N11*(1+$D11) -> 0
C12: Total Gross Income | E12: =+SUM(E9:E11) -> 1547612 | F12: =+SUM(F9:F11) -> 563992.2 | G12: =+SUM(G9:G11) -> 580911.97 | H12: =+SUM(H9:H11) -> 598339.32 | I12: =+SUM(I9:I11) -> 616289.5 | J12: =+SUM(J9:J11) -> 634778.19 | K12: =+SUM(K9:K11) -> 653821.54 | L12: =+SUM(L9:L11) -> 673436.18 | ... O12: =+SUM(O9:O11) -> 735881.9
C13: Gross Income Growth | E13: -- | F13: =+F12/E12-1 -> -0.63557261 | G13: =+G12/F12-1 -> 0.03 | H13: =+H12/G12-1 -> 0.03 | I13: =+I12/H12-1 -> 0.03 | J13: =+J12/I12-1 -> 0.03 | K13: =+K12/J12-1 -> 0.03 | L13: =+L12/K12-1 -> 0.03 | M13: =+M12/L12-1 -> 0.03 | ... O13: =+O12/N12-1 -> 0.03
C15: Opertating Expenses
A17: BAD
C18: Bad Debt | E18: =+'Scenario 0'!E18 -> 0 | F18: =+'Scenario 0'!F18 -> 0 | G18: =+'Scenario 0'!G18 -> 0 | H18: =+'Scenario 0'!H18 -> 0 | I18: =+'Scenario 0'!I18 -> 0 | J18: =+'Scenario 0'!J18 -> 0 | K18: =+'Scenario 0'!K18 -> 0 | L18: =+'Scenario 0'!L18 -> 0 | ... O18: =+'Scenario 0'!O18 -> 0
A20: RES
A21: COM
C22: Total Replacement Reserves | E22: =+'Scenario 0'!E22 -> 21600 | F22: =+'Scenario 0'!F22 -> 21600 | G22: =+'Scenario 0'!G22 -> 21600 | H22: =+'Scenario 0'!H22 -> 21600 | I22: =+'Scenario 0'!I22 -> 21600 | J22: =+'Scenario 0'!J22 -> 21600 | K22: =+'Scenario 0'!K22 -> 21600 | L22: =+'Scenario 0'!L22 -> 21600 | ... O22: =+'Scenario 0'!O22 -> 21600
A24: MAN
A25: ASS
A26: PAY
A27: MAIT
C28: Payroll | E28: =+'Scenario 0'!E29 -> 0 | F28: =+'Scenario 0'!F29 -> 126720 | G28: =+'Scenario 0'!G29 -> 130521.6 | H28: =+'Scenario 0'!H29 -> 134437.25 | I28: =+'Scenario 0'!I29 -> 138470.37 | J28: =+'Scenario 0'!J29 -> 142624.48 | K28: =+'Scenario 0'!K29 -> 146903.21 | L28: =+'Scenario 0'!L29 -> 151310.31 | ... O28: =+'Scenario 0'!O29 -> 165340.86
A30: MGMT
A31: LEGAL
A32: OFF
A33: TRAVEL
A34: AUD
A35: ADV
A36: TRAIN
A37: BANK
A38: BOOK
A39: PAYSERV
A40: UNIT
A41: MISCAD
C42: Admin Expenses | E42: =+'Scenario 0'!E43 -> 0 | F42: =+'Scenario 0'!F43 -> 59499.61 | G42: =+'Scenario 0'!G43 -> 61284.598 | H42: =+'Scenario 0'!H43 -> 63123.136 | I42: =+'Scenario 0'!I43 -> 65016.83 | J42: =+'Scenario 0'!J43 -> 66967.335 | K42: =+'Scenario 0'!K43 -> 68976.355 | L42: =+'Scenario 0'!L43 -> 71045.646 | ... O42: =+'Scenario 0'!O43 -> 77633.496
A44: ELEC
A45: VAC
A46: WS
A47: GAS
A48: CABLE
A49: TRASH
...

Sheet Scenario 2
C1: Underwriting Model Scenario 2
D3: Year | E3: =+'Scenario 0'!E3 -> 2024 | F3: =+'Scenario 0'!F3 -> 2025 | G3: =+'Scenario 0'!G3 -> 2026 | H3: =+'Scenario 0'!H3 -> 2027 | I3: =+'Scenario 0'!I3 -> 2028 | J3: =+'Scenario 0'!J3 -> 2029 | K3: =+'Scenario 0'!K3 -> 2030 | L3: =+'Scenario 0'!L3 -> 2031 | ... O3: =+'Scenario 0'!O3 -> 2034
C4: ='Unit Mix'!$W$3 -> Scenario 2 (Max Net LIHTC)
C6: Income Statement | E6: =+'Scenario 0'!E6 -> T12 | F6: =+'Scenario 0'!F6 -> 1 | G6: =+'Scenario 0'!G6 -> 2 | H6: =+'Scenario 0'!H6 -> 3 | I6: =+'Scenario 0'!I6 -> 4 | J6: =+'Scenario 0'!J6 -> 5 | K6: =+'Scenario 0'!K6 -> 6 | L6: =+'Scenario 0'!L6 -> 7 | ... O6: =+'Scenario 0'!O6 -> 10
C7: Gross Potential Income | E7: =+'Scenario 0'!$E$7 -> 1561954 | F7: =+'Unit Mix'!AB26 -> 640308 | G7: =+'Unit Mix'!AB49 -> 659517.24 | H7: =+'Unit Mix'!AB72 -> 679302.76 | I7: =+'Unit Mix'!AB95 -> 699681.84 | J7: =+'Unit Mix'!AB118 -> 720672.3 | K7: =+'Unit Mix'!AB141 -> 742292.46 | L7: =+'Unit Mix'!AB164 -> 764561.24 | M7: =+'Unit Mix'!AB187 -> 787498.08 | N7: =+'Unit Mix'!AB210 -> 811123.02 | O7: =+'Unit Mix'!AB233 -> 835456.71
C8: Vacancy Factor | D8: =+Dashboard!$P$10 -> 0.05 | E8: =+'Scenario 0'!$E$8 -> 48058 | F8: =+F7*$D$8 -> 32015.4 | G8: =+G7*$D$8 -> 32975.862 | H8: =+H7*$D$8 -> 33965.138 | I8: =+I7*$D$8 -> 34984.092 | J8: =+J7*$D$8 -> 36033.615 | K8: =+K7*$D$8 -> 37114.623 | L8: =+L7*$D$8 -> 38228.062 | M8: =+M7*$D$8 -> 39374.904 | ... O8: =+O7*$D$8 -> 41772.835
C9: Net Rental Income | E9: =+E7-E8 -> 1513896 | F9: =+F7-F8 -> 608292.6 | G9: =+G7-G8 -> 626541.38 | H9: =+H7-H8 -> 645337.62 | I9: =+I7-I8 -> 664697.75 | J9: =+J7-J8 -> 684638.68 | K9: =+K7-K8 -> 705177.84 | L9: =+L7-L8 -> 726333.18 | ... O9: =+O7-O8 -> 793683.87
C11: Laundry and Other Income | D11: =+Dashboard!$P$14 -> 0.025 | E11: =+'Scenario 0'!$E$11 -> 33716 | F11: =+Dashboard!$O$14 -> 0 | G11: =+F11*(1+$D11) -> 0 | H11: =+G11*(1+$D11) -> 0 | I11: =+H11*(1+$D11) -> 0 | J11: =+I11*(1+$D11) -> 0 | K11: =+J11*(1+$D11) -> 0 | L11: =+K11*(1+$D11) -> 0 | M11: =+L11*(1+$D11) -> 0 | N11: =+M11*(1+$D11) -> 0 | O11: =+N11*(1+$D11) -> 0
C12: Total Gross Income | E12: =+SUM(E9:E11) -> 1547612 | F12: =+SUM(F9:F11) -> 608292.6 | G12: =+SUM(G9:G11) -> 626541.38 | H12: =+SUM(H9:H11) -> 645337.62 | I12: =+SUM(I9:I11) -> 664697.75 | J12: =+SUM(J9:J11) -> 684638.68 | K12: =+SUM(K9:K11) -> 705177.84 | L12: =+SUM(L9:L11) -> 726333.18 | ... O12: =+SUM(O9:O11) -> 793683.87
C13: Gross Income Growth | E13: -- | F13: =+F12/E12-1 -> -0.60694761 | G13: =+G12/F12-1 -> 0.03 | H13: =+H12/G12-1 -> 0.03 | I13: =+I12/H12-1 -> 0.03 | J13: =+J12/I12-1 -> 0.03 | K13: =+K12/J12-1 -> 0.03 | L13: =+L12/K12-1 -> 0.03 | M13: =+M12/L12-1 -> 0.03 | ... O13: =+O12/N12-1 -> 0.03
C15: Opertating Expenses
A17: BAD
C18: Bad Debt | E18: =+'Scenario 0'!E18 -> 0 | F18: =+'Scenario 0'!F18 -> 0 | G18: =+'Scenario 0'!G18 -> 0 | H18: =+'Scenario 0'!H18 -> 0 | I18: =+'Scenario 0'!I18 -> 0 | J18: =+'Scenario 0'!J18 -> 0 | K18: =+'Scenario 0'!K18 -> 0 | L18: =+'Scenario 0'!L18 -> 0 | ... O18: =+'Scenario 0'!O18 -> 0
A20: RES
A21: COM
C22: Total Replacement Reserves | E22: =+'Scenario 0'!E22 -> 21600 | F22: =+'Scenario 0'!F22 -> 21600 | G22: =+'Scenario 0'!G22 -> 21600 | H22: =+'Scenario 0'!H22 -> 21600 | I22: =+'Scenario 0'!I22 -> 21600 | J22: =+'Scenario 0'!J22 -> 21600 | K22: =+'Scenario 0'!K22 -> 21600 | L22: =+'Scenario 0'!L22 -> 21600 | ... O22: =+'Scenario 0'!O22 -> 21600
A24: MAN
A25: ASS
A26: PAY
A27: MAIT
C28: Payroll | E28: =+'Scenario 0'!E29 -> 0 | F28: =+'Scenario 0'!F29 -> 126720 | G28: =+'Scenario 0'!G29 -> 130521.6 | H28: =+'Scenario 0'!H29 -> 134437.25 | I28: =+'Scenario 0'!I29 -> 138470.37 | J28: =+'Scenario 0'!J29 -> 142624.48 | K28: =+'Scenario 0'!K29 -> 146903.21 | L28: =+'Scenario 0'!L29 -> 151310.31 | ... O28: =+'Scenario 0'!O29 -> 165340.86
A30: MGMT
A31: LEGAL
A32: OFF
A33: TRAVEL
A34: AUD
A35: ADV
A36: TRAIN
A37: BANK
A38: BOOK
A39: PAYSERV
A40: UNIT
A41: MISCAD
C42: Admin Expenses | E42: =+'Scenario 0'!E43 -> 0 | F42: =+'Scenario 0'!F43 -> 59499.61 | G42: =+'Scenario 0'!G43 -> 61284.598 | H42: =+'Scenario 0'!H43 -> 63123.136 | I42: =+'Scenario 0'!I43 -> 65016.83 | J42: =+'Scenario 0'!J43 -> 66967.335 | K42: =+'Scenario 0'!K43 -> 68976.355 | L42: =+'Scenario 0'!L43 -> 71045.646 | ... O42: =+'Scenario 0'!O43 -> 77633.496
A44: ELEC
A45: VAC
A46: WS
A47: GAS
A48: CABLE
A49: TRASH
...

Sheet Scenario 3
C1: Underwriting Model Scenario 3
D3: Year | E3: =+'Scenario 0'!E3 -> 2024 | F3: =+'Scenario 0'!F3 -> 2025 | G3: =+'Scenario 0'!G3 -> 2026 | H3: =+'Scenario 0'!H3 -> 2027 | I3: =+'Scenario 0'!I3 -> 2028 | J3: =+'Scenario 0'!J3 -> 2029 | K3: =+'Scenario 0'!K3 -> 2030 | L3: =+'Scenario 0'!L3 -> 2031 | ... O3: =+'Scenario 0'!O3 -> 2034
C4: =+'Unit Mix'!AD3 -> Scenario 3 ( Max Current Vouchers + NET LIHTC)
C6: Income Statement | E6: =+'Scenario 0'!E6 -> T12 | F6: =+'Scenario 0'!F6 -> 1 | G6: =+'Scenario 0'!G6 -> 2 | H6: =+'Scenario 0'!H6 -> 3 | I6: =+'Scenario 0'!I6 -> 4 | J6: =+'Scenario 0'!J6 -> 5 | K6: =+'Scenario 0'!K6 -> 6 | L6: =+'Scenario 0'!L6 -> 7 | ... O6: =+'Scenario 0'!O6 -> 10
C7: Gross Potential Income | E7: =+'Scenario 0'!$E$7 -> 1561954 | F7: =+'Unit Mix'!AI26 -> 656580 | G7: =+'Unit Mix'!AI49 -> 676277.4 | H7: =+'Unit Mix'!AI72 -> 696565.72 | I7: =+'Unit Mix'!AI95 -> 717462.69 | J7: =+'Unit Mix'!AI118 -> 738986.57 | K7: =+'Unit Mix'!AI141 -> 761156.17 | L7: =+'Unit Mix'!AI164 -> 783990.86 | M7: =+'Unit Mix'!AI187 -> 807510.58 | N7: =+'Unit Mix'!AI210 -> 831735.9 | O7: =+'Unit Mix'!AI233 -> 856687.98
C8: Vacancy Factor | D8: =+Dashboard!$P$10 -> 0.05 | E8: =+'Scenario 0'!$E$8 -> 48058 | F8: =+F7*$D$8 -> 32829 | G8: =+G7*$D$8 -> 33813.87 | H8: =+H7*$D$8 -> 34828.286 | I8: =+I7*$D$8 -> 35873.135 | J8: =+J7*$D$8 -> 36949.329 | K8: =+K7*$D$8 -> 38057.809 | L8: =+L7*$D$8 -> 39199.543 | M8: =+M7*$D$8 -> 40375.529 | ... O8: =+O7*$D$8 -> 42834.399
C9: Net Rental Income | E9: =+E7-E8 -> 1513896 | F9: =+F7-F8 -> 623751 | G9: =+G7-G8 -> 642463.53 | H9: =+H7-H8 -> 661737.44 | I9: =+I7-I8 -> 681589.56 | J9: =+J7-J8 -> 702037.25 | K9: =+K7-K8 -> 723098.36 | L9: =+L7-L8 -> 744791.31 | ... O9: =+O7-O8 -> 813853.58
C11: Laundry and Other Income | D11: =+Dashboard!$P$14 -> 0.025 | E11: =+'Scenario 0'!$E$11 -> 33716 | F11: =+Dashboard!$O$14 -> 0 | G11: =+F11*(1+$D11) -> 0 | H11: =+G11*(1+$D11) -> 0 | I11: =+H11*(1+$D11) -> 0 | J11: =+I11*(1+$D11) -> 0 | K11: =+J11*(1+$D11) -> 0 | L11: =+K11*(1+$D11) -> 0 | M11: =+L11*(1+$D11) -> 0 | N11: =+M11*(1+$D11) -> 0 | O11: =+N11*(1+$D11) -> 0
C12: Total Gross Income | E12: =+SUM(E9:E11) -> 1547612 | F12: =+SUM(F9:F11) -> 623751 | G12: =+SUM(G9:G11) -> 642463.53 | H12: =+SUM(H9:H11) -> 661737.44 | I12: =+SUM(I9:I11) -> 681589.56 | J12: =+SUM(J9:J11) -> 702037.25 | K12: =+SUM(K9:K11) -> 723098.36 | L12: =+SUM(L9:L11) -> 744791.31 | ... O12: =+SUM(O9:O11) -> 813853.58
C13: Gross Income Growth | E13: -- | F13: =+F12/E12-1 -> -0.59695906 | G13: =+G12/F12-1 -> 0.03 | H13: =+H12/G12-1 -> 0.03 | I13: =+I12/H12-1 -> 0.03 | J13: =+J12/I12-1 -> 0.03 | K13: =+K12/J12-1 -> 0.03 | L13: =+L12/K12-1 -> 0.03 | M13: =+M12/L12-1 -> 0.03 | ... O13: =+O12/N12-1 -> 0.03
C15: Opertating Expenses
A17: BAD
C18: Bad Debt | E18: =+'Scenario 0'!E18 -> 0 | F18: =+'Scenario 0'!F18 -> 0 | G18: =+'Scenario 0'!G18 -> 0 | H18: =+'Scenario 0'!H18 -> 0 | I18: =+'Scenario 0'!I18 -> 0 | J18: =+'Scenario 0'!J18 -> 0 | K18: =+'Scenario 0'!K18 -> 0 | L18: =+'Scenario 0'!L18 -> 0 | ... O18: =+'Scenario 0'!O18 -> 0
A20: RES
A21: COM
C22: Total Replacement Reserves | E22: =+'Scenario 0'!E22 -> 21600 | F22: =+'Scenario 0'!F22 -> 21600 | G22: =+'Scenario 0'!G22 -> 21600 | H22: =+'Scenario 0'!H22 -> 21600 | I22: =+'Scenario 0'!I22 -> 21600 | J22: =+'Scenario 0'!J22 -> 21600 | K22: =+'Scenario 0'!K22 -> 21600 | L22: =+'Scenario 0'!L22 -> 21600 | ... O22: =+'Scenario 0'!O22 -> 21600
A24: MAN
A25: ASS
A26: PAY
A27: MAIT
C28: Payroll | E28: =+'Scenario 0'!E29 -> 0 | F28: =+'Scenario 0'!F29 -> 126720 | G28: =+'Scenario 0'!G29 -> 130521.6 | H28: =+'Scenario 0'!H29 -> 134437.25 | I28: =+'Scenario 0'!I29 -> 138470.37 | J28: =+'Scenario 0'!J29 -> 142624.48 | K28: =+'Scenario 0'!K29 -> 146903.21 | L28: =+'Scenario 0'!L29 -> 151310.31 | ... O28: =+'Scenario 0'!O29 -> 165340.86
A30: MGMT
A31: LEGAL
A32: OFF
A33: TRAVEL
A34: AUD
A35: ADV
A36: TRAIN
A37: BANK
A38: BOOK
A39: PAYSERV
A40: UNIT
A41: MISCAD
C42: Admin Expenses | E42: =+'Scenario 0'!E43 -> 0 | F42: =+'Scenario 0'!F43 -> 59499.61 | G42: =+'Scenario 0'!G43 -> 61284.598 | H42: =+'Scenario 0'!H43 -> 63123.136 | I42: =+'Scenario 0'!I43 -> 65016.83 | J42: =+'Scenario 0'!J43 -> 66967.335 | K42: =+'Scenario 0'!K43 -> 68976.355 | L42: =+'Scenario 0'!L43 -> 71045.646 | ... O42: =+'Scenario 0'!O43 -> 77633.496
A44: ELEC
A45: VAC
A46: WS
A47: GAS
A48: CABLE
A49: TRASH
...

Sheet Rent Roll Calcs -->

Sheet Unit Mix
B3: Scenario 0 (No Change to Asset) | P3: Scenario 1 ( Max Current Vouchers) | W3: Scenario 2 (Max Net LIHTC) | AD3: Scenario 3 ( Max Current Vouchers + NET LIHTC)
B5: Year 1 | P5: =+$B5 -> Year 1 | W5: =+$B5 -> Year 1 | AD5: =+$B5 -> Year 1
B6: Unit Type | C6: AMI / S8 | D6: # of Units | E6: Avg. SF | F6: Avg. Utilities | G6: Avg. Max LITHC | H6: Net LIHTC | I6: Avg. Max FMR | J6: Net FMR | K6: CoStar Rent | L6: Gross Rent | M6: Avg. Current Rent | N6: Yrly. Gross Income (Net Rent) | P6: Unit Type | Q6: AMI / S8 | R6: # of Units | S6: Avg. SF | T6: Avg. Utilities | U6: Max Current Vouchers | W6: Unit Type | X6: AMI / S8 | Y6: # of Units | Z6: Avg. SF | AA6: Avg. Utilities | AB6: Max NET LIHTC | AD6: Unit Type | AE6: AMI / S8 | AF6: # of Units | AG6: Avg. SF | AH6: Avg. Utilities | AI6: Max Current Vouchers + NET LIHTC
B7: ='Rent Roll'!C13 -> 1x1 | C7: ='Rent Roll'!D13 -> 50% AMI | D7: ='Rent Roll'!E13 -> 2 | E7: ='Rent Roll'!F13 -> 701 | F7: ='Rent Roll'!K13 -> 65 | G7: ='Rent Roll'!M13 -> 651 | H7: =+G7-F7 -> 586 | I7: ='Rent Roll'!O13 -> 683 | J7: =I7-F7 -> 618 | K7: ='Rent Roll'!G13 -> 0 | L7: ='Rent Roll'!L13 -> 592 | M7: ='Rent Roll'!J13 -> 527 | N7: =((M7*D7)*12) -> 12648 | P7: =B7 -> 1x1 | Q7: =C7 -> 50% AMI | R7: =D7 -> 2 | S7: =E7 -> 701 | T7: =F7 -> 65 | U7: =((M7*R7)*12) -> 12648 | W7: =B7 -> 1x1 | X7: =C7 -> 50% AMI | Y7: =D7 -> 2 | Z7: =E7 -> 701 | AA7: =F7 -> 65 | AB7: =((H7*Y7)*12) -> 14064 | AD7: =B7 -> 1x1 | AE7: =C7 -> 50% AMI | AF7: =D7 -> 2 | AG7: =E7 -> 701 | AH7: =F7 -> 65 | AI7: =+MAX(U7,AB7) -> 14064
B8: ='Rent Roll'!C14 -> 1x1 | C8: ='Rent Roll'!D14 -> 60% AMI | D8: ='Rent Roll'!E14 -> 0 | E8: ='Rent Roll'!F14 -> 701 | F8: ='Rent Roll'!K14 -> 65 | G8: ='Rent Roll'!M14 -> 781 | H8: =+G8-F8 -> 716 | I8: ='Rent Roll'!O14 -> 683 | J8: =I8-F8 -> 618 | K8: ='Rent Roll'!G14 -> 0 | L8: ='Rent Roll'!L14 -> 65 | M8: ='Rent Roll'!J14 -> 0 | N8: =((M8*D8)*12) -> 0 | P8: =B8 -> 1x1 | Q8: =C8 -> 60% AMI | R8: =D8 -> 0 | S8: =E8 -> 701 | T8: =F8 -> 65 | U8: =((M8*R8)*12) -> 0 | W8: =B8 -> 1x1 | X8: =C8 -> 60% AMI | Y8: =D8 -> 0 | Z8: =E8 -> 701 | AA8: =F8 -> 65 | AB8: =((H8*Y8)*12) -> 0 | AD8: =B8 -> 1x1 | AE8: =C8 -> 60% AMI | AF8: =D8 -> 0 | AG8: =E8 -> 701 | AH8: =F8 -> 65 | AI8: =+MAX(U8,AB8) -> 0
B9: ='Rent Roll'!C15 -> 1x1 | C9: ='Rent Roll'!D15 -> Market | D9: ='Rent Roll'!E15 -> 1 | E9: ='Rent Roll'!F15 -> 701 | F9: ='Rent Roll'!K15 -> 0 | G9: ='Rent Roll'!M15 -> 0 | H9: =+G9-F9 -> 0 | I9: ='Rent Roll'!O15 -> 683 | J9: =I9-F9 -> 683 | K9: ='Rent Roll'!G15 -> 0 | L9: ='Rent Roll'!L15 -> 593 | M9: ='Rent Roll'!J15 -> 593 | N9: =((M9*D9)*12) -> 7116 | P9: =B9 -> 1x1 | Q9: =C9 -> Market | R9: =D9 -> 1 | S9: =E9 -> 701 | T9: =F9 -> 0 | U9: =((M9*R9)*12) -> 7116 | W9: =B9 -> 1x1 | X9: =C9 -> Market | Y9: =D9 -> 1 | Z9: =E9 -> 701 | AA9: =F9 -> 0 | AB9: =((H9*Y9)*12) -> 0 | AD9: =B9 -> 1x1 | AE9: =C9 -> Market | AF9: =D9 -> 1 | AG9: =E9 -> 701 | AH9: =F9 -> 0 | AI9: =+MAX(U9,AB9) -> 7116
B10: ='Rent Roll'!C16 -> 1x1 | C10: ='Rent Roll'!D16 -> S8 Voucher | D10: ='Rent Roll'!E16 -> 3 | E10: ='Rent Roll'!F16 -> 701 | F10: ='Rent Roll'!K16 -> 65 | G10: ='Rent Roll'!M16 -> 781 | H10: =+G10-F10 -> 716 | I10: ='Rent Roll'!O16 -> 683 | J10: =I10-F10 -> 618 | K10: ='Rent Roll'!G16 -> 0 | L10: ='Rent Roll'!L16 -> 588 | M10: ='Rent Roll'!J16 -> 523 | N10: =((M10*D10)*12) -> 18828 | P10: =B10 -> 1x1 | Q10: =C10 -> S8 Voucher | R10: =D10 -> 3 | S10: =E10 -> 701 | T10: =F10 -> 65 | U10: =((M10*R10)*12) -> 18828 | W10: =B10 -> 1x1 | X10: =C10 -> S8 Voucher | Y10: =D10 -> 3 | Z10: =E10 -> 701 | AA10: =F10 -> 65 | AB10: =((H10*Y10)*12) -> 25776 | AD10: =B10 -> 1x1 | AE10: =C10 -> S8 Voucher | AF10: =D10 -> 3 | AG10: =E10 -> 701 | AH10: =F10 -> 65 | AI10: =+MAX(U10,AB10) -> 25776
B11: ='Rent Roll'!C17 -> 2x1.5 | C11: ='Rent Roll'!D17 -> 40% AMI | D11: ='Rent Roll'!E17 -> 1 | E11: ='Rent Roll'!F17 -> 940 | F11: ='Rent Roll'!K17 -> 86 | G11: ='Rent Roll'!M17 -> 539 | H11: =+G11-F11 -> 453 | I11: ='Rent Roll'!O17 -> 778 | J11: =I11-F11 -> 692 | K11: ='Rent Roll'!G17 -> 0 | L11: ='Rent Roll'!L17 -> 551 | M11: ='Rent Roll'!J17 -> 465 | N11: =((M11*D11)*12) -> 5580 | P11: =B11 -> 2x1.5 | Q11: =C11 -> 40% AMI | R11: =D11 -> 1 | S11: =E11 -> 940 | T11: =F11 -> 86 | U11: =((M11*R11)*12) -> 5580 | W11: =B11 -> 2x1.5 | X11: =C11 -> 40% AMI | Y11: =D11 -> 1 | Z11: =E11 -> 940 | AA11: =F11 -> 86 | AB11: =((H11*Y11)*12) -> 5436 | AD11: =B11 -> 2x1.5 | AE11: =C11 -> 40% AMI | AF11: =D11 -> 1 | AG11: =E11 -> 940 | AH11: =F11 -> 86 | AI11: =+MAX(U11,AB11) -> 5580
B12: ='Rent Roll'!C18 -> 2x1.5 | C12: ='Rent Roll'!D18 -> 50% AMI | D12: ='Rent Roll'!E18 -> 3 | E12: ='Rent Roll'!F18 -> 990 | F12: ='Rent Roll'!K18 -> 86 | G12: ='Rent Roll'!M18 -> 695 | H12: =+G12-F12 -> 609 | I12: ='Rent Roll'!O18 -> 778 | J12: =I12-F12 -> 692 | K12: ='Rent Roll'!G18 -> 0 | L12: ='Rent Roll'!L18 -> 666 | M12: ='Rent Roll'!J18 -> 580 | N12: =((M12*D12)*12) -> 20880 | P12: =B12 -> 2x1.5 | Q12: =C12 -> 50% AMI | R12: =D12 -> 3 | S12: =E12 -> 990 | T12: =F12 -> 86 | U12: =((M12*R12)*12) -> 20880 | W12: =B12 -> 2x1.5 | X12: =C12 -> 50% AMI | Y12: =D12 -> 3 | Z12: =E12 -> 990 | AA12: =F12 -> 86 | AB12: =((H12*Y12)*12) -> 21924 | AD12: =B12 -> 2x1.5 | AE12: =C12 -> 50% AMI | AF12: =D12 -> 3 | AG12: =E12 -> 990 | AH12: =F12 -> 86 | AI12: =+MAX(U12,AB12) -> 21924
B13: ='Rent Roll'!C19 -> 2x1.5 | C13: ='Rent Roll'!D19 -> 60% AMI | D13: ='Rent Roll'!E19 -> 2 | E13: ='Rent Roll'!F19 -> 980 | F13: ='Rent Roll'!K19 -> 86 | G13: ='Rent Roll'!M19 -> 851 | H13: =+G13-F13 -> 765 | I13: ='Rent Roll'!O19 -> 778 | J13: =I13-F13 -> 692 | K13: ='Rent Roll'!G19 -> 0 | L13: ='Rent Roll'!L19 -> 728 | M13: ='Rent Roll'!J19 -> 642 | N13: =((M13*D13)*12) -> 15408 | P13: =B13 -> 2x1.5 | Q13: =C13 -> 60% AMI | R13: =D13 -> 2 | S13: =E13 -> 980 | T13: =F13 -> 86 | U13: =((M13*R13)*12) -> 15408 | W13: =B13 -> 2x1.5 | X13: =C13 -> 60% AMI | Y13: =D13 -> 2 | Z13: =E13 -> 980 | AA13: =F13 -> 86 | AB13: =((H13*Y13)*12) -> 18360 | AD13: =B13 -> 2x1.5 | AE13: =C13 -> 60% AMI | AF13: =D13 -> 2 | AG13: =E13 -> 980 | AH13: =F13 -> 86 | AI13: =+MAX(U13,AB13) -> 18360
B14: ='Rent Roll'!C20 -> 2x2 | C14: ='Rent Roll'!D20 -> 50% AMI | D14: ='Rent Roll'!E20 -> 1 | E14: ='Rent Roll'!F20 -> 968 | F14: ='Rent Roll'!K20 -> 86 | G14: ='Rent Roll'!M20 -> 695 | H14: =+G14-F14 -> 609 | I14: ='Rent Roll'!O20 -> 778 | J14: =I14-F14 -> 692 | K14: ='Rent Roll'!G20 -> 0 | L14: ='Rent Roll'!L20 -> 696 | M14: ='Rent Roll'!J20 -> 610 | N14: =((M14*D14)*12) -> 7320 | P14: =B14 -> 2x2 | Q14: =C14 -> 50% AMI | R14: =D14 -> 1 | S14: =E14 -> 968 | T14: =F14 -> 86 | U14: =((M14*R14)*12) -> 7320 | W14: =B14 -> 2x2 | X14: =C14 -> 50% AMI | Y14: =D14 -> 1 | Z14: =E14 -> 968 | AA14: =F14 -> 86 | AB14: =((H14*Y14)*12) -> 7308 | AD14: =B14 -> 2x2 | AE14: =C14 -> 50% AMI | AF14: =D14 -> 1 | AG14: =E14 -> 968 | AH14: =F14 -> 86 | AI14: =+MAX(U14,AB14) -> 7320
B15: ='Rent Roll'!C21 -> 2x2 | C15: ='Rent Roll'!D21 -> 60% AMI | D15: ='Rent Roll'!E21 -> 2 | E15: ='Rent Roll'!F21 -> 968 | F15: ='Rent Roll'!K21 -> 86 | G15: ='Rent Roll'!M21 -> 851 | H15: =+G15-F15 -> 765 | I15: ='Rent Roll'!O21 -> 778 | J15: =I15-F15 -> 692 | K15: ='Rent Roll'!G21 -> 0 | L15: ='Rent Roll'!L21 -> 721 | M15: ='Rent Roll'!J21 -> 635 | N15: =((M15*D15)*12) -> 15240 | P15: =B15 -> 2x2 | Q15: =C15 -> 60% AMI | R15: =D15 -> 2 | S15: =E15 -> 968 | T15: =F15 -> 86 | U15: =((M15*R15)*12) -> 15240 | W15: =B15 -> 2x2 | X15: =C15 -> 60% AMI | Y15: =D15 -> 2 | Z15: =E15 -> 968 | AA15: =F15 -> 86 | AB15: =((H15*Y15)*12) -> 18360 | AD15: =B15 -> 2x2 | AE15: =C15 -> 60% AMI | AF15: =D15 -> 2 | AG15: =E15 -> 968 | AH15: =F15 -> 86 | AI15: =+MAX(U15,AB15) -> 18360
B16: ='Rent Roll'!C22 -> 2x2 | C16: ='Rent Roll'!D22 -> Market | D16: ='Rent Roll'!E22 -> 0 | E16: ='Rent Roll'!F22 -> 968 | F16: ='Rent Roll'!K22 -> 0 | G16: ='Rent Roll'!M22 -> 0 | H16: =+G16-F16 -> 0 | I16: ='Rent Roll'!O22 -> 778 | J16: =I16-F16 -> 778 | K16: ='Rent Roll'!G22 -> 0 | L16: ='Rent Roll'!L22 -> 0 | M16: ='Rent Roll'!J22 -> 0 | N16: =((M16*D16)*12) -> 0 | P16: =B16 -> 2x2 | Q16: =C16 -> Market | R16: =D16 -> 0 | S16: =E16 -> 968 | T16: =F16 -> 0 | U16: =((M16*R16)*12) -> 0 | W16: =B16 -> 2x2 | X16: =C16 -> Market | Y16: =D16 -> 0 | Z16: =E16 -> 968 | AA16: =F16 -> 0 | AB16: =((H16*Y16)*12) -> 0 | AD16: =B16 -> 2x2 | AE16: =C16 -> Market | AF16: =D16 -> 0 | AG16: =E16 -> 968 | AH16: =F16 -> 0 | AI16: =+MAX(U16,AB16) -> 0
B17: ='Rent Roll'!C23 -> 2x2 (TH) | C17: ='Rent Roll'!D23 -> 40% AMI | D17: ='Rent Roll'!E23 -> 1 | E17: ='Rent Roll'!F23 -> 1058 | F17: ='Rent Roll'!K23 -> 86 | G17: ='Rent Roll'!M23 -> 539 | H17: =+G17-F17 -> 453 | I17: ='Rent Roll'!O23 -> 778 | J17: =I17-F17 -> 692 | K17: ='Rent Roll'!G23 -> 0 | L17: ='Rent Roll'!L23 -> 536 | M17: ='Rent Roll'!J23 -> 450 | N17: =((M17*D17)*12) -> 5400 | P17: =B17 -> 2x2 (TH) | Q17: =C17 -> 40% AMI | R17: =D17 -> 1 | S17: =E17 -> 1058 | T17: =F17 -> 86 | U17: =((M17*R17)*12) -> 5400 | W17: =B17 -> 2x2 (TH) | X17: =C17 -> 40% AMI | Y17: =D17 -> 1 | Z17: =E17 -> 1058 | AA17: =F17 -> 86 | AB17: =((H17*Y17)*12) -> 5436 | AD17: =B17 -> 2x2 (TH) | AE17: =C17 -> 40% AMI | AF17: =D17 -> 1 | AG17: =E17 -> 1058 | AH17: =F17 -> 86 | AI17: =+MAX(U17,AB17) -> 5436
B18: ='Rent Roll'!C24 -> 2x2 (TH) | C18: ='Rent Roll'!D24 -> 50% AMI | D18: ='Rent Roll'!E24 -> 1 | E18: ='Rent Roll'!F24 -> 1058 | F18: ='Rent Roll'!K24 -> 86 | G18: ='Rent Roll'!M24 -> 695 | H18: =+G18-F18 -> 609 | I18: ='Rent Roll'!O24 -> 778 | J18: =I18-F18 -> 692 | K18: ='Rent Roll'!G24 -> 0 | L18: ='Rent Roll'!L24 -> 146 | M18: ='Rent Roll'!J24 -> 60 | N18: =((M18*D18)*12) -> 720 | P18: =B18 -> 2x2 (TH) | Q18: =C18 -> 50% AMI | R18: =D18 -> 1 | S18: =E18 -> 1058 | T18: =F18 -> 86 | U18: =((M18*R18)*12) -> 720 | W18: =B18 -> 2x2 (TH) | X18: =C18 -> 50% AMI | Y18: =D18 -> 1 | Z18: =E18 -> 1058 | AA18: =F18 -> 86 | AB18: =((H18*Y18)*12) -> 7308 | AD18: =B18 -> 2x2 (TH) | AE18: =C18 -> 50% AMI | AF18: =D18 -> 1 | AG18: =E18 -> 1058 | AH18: =F18 -> 86 | AI18: =+MAX(U18,AB18) -> 7308
... B25: ='Rent Roll'!C31 -> 3x2 (TH) | C25: ='Rent Roll'!D31 -> S8 Voucher | D25: ='Rent Roll'!E31 -> 11 | E25: ='Rent Roll'!F31 -> 1296 | F25: ='Rent Roll'!K31 -> 107 | G25: ='Rent Roll'!M31 -> 976 | H25: =+G25-F25 -> 869 | I25: ='Rent Roll'!O31 -> 1023 | J25: =I25-F25 -> 916 | K25: ='Rent Roll'!G31 -> 0 | L25: ='Rent Roll'!L31 -> 935 | M25: ='Rent Roll'!J31 -> 828 | N25: =((M25*D25)*12) -> 109296 | P25: =B25 -> 3x2 (TH) | Q25: =C25 -> S8 Voucher | R25: =D25 -> 11 | S25: =E25 -> 1296 | T25: =F25 -> 107 | U25: =((M25*R25)*12) -> 109296 | W25: =B25 -> 3x2 (TH) | X25: =C25 -> S8 Voucher | Y25: =D25 -> 11 | Z25: =E25 -> 1296 | AA25: =F25 -> 107 | AB25: =((H25*Y25)*12) -> 114708 | AD25: =B25 -> 3x2 (TH) | AE25: =C25 -> S8 Voucher | AF25: =D25 -> 11 | AG25: =E25 -> 1296 | AH25: =F25 -> 107 | AI25: =+MAX(U25,AB25) -> 114708
B26: Total (Pre-Vacancy) | D26: =SUM(D7:D25) -> 72 | E26: =+SUMPRODUCT(E7:E25,$D7:$D25) -> 59002 | F26: =+SUMPRODUCT(F7:F25,$D7:$D25) -> 6335 | G26: =+SUMPRODUCT(G7:G25,$D7:$D25) -> 59694 | H26: =+SUMPRODUCT(H7:H25,$D7:$D25) -> 53359 | I26: =+SUMPRODUCT(I7:I25,$D7:$D25) -> 60346 | J26: =+SUMPRODUCT(J7:J25,$D7:$D25) -> 54011 | K26: =+SUMPRODUCT(K7:K25,$D7:$D25) -> 0 | L26: =+SUMPRODUCT(L7:L25,$D7:$D25) -> 55808 | M26: =+SUMPRODUCT(M7:M25,$D7:$D25) -> 49473 | N26: =SUM(N7:N25) -> 593676 | P26: Total (Pre-Vacancy) | R26: =SUM(R7:R25) -> 72 | S26: =+SUMPRODUCT(S7:S25,$R7:$R25) -> 59002 | T26: =+SUMPRODUCT(T7:T25,$R7:$R25) -> 6335 | U26: =SUM(U7:U25) -> 593676 | W26: Total (Pre-Vacancy) | Y26: =SUM(Y7:Y25) -> 72 | Z26: =+SUMPRODUCT(Z7:Z25,$Y7:$Y25) -> 59002 | AA26: =+SUMPRODUCT(AA7:AA25,$Y7:$Y25) -> 6335 | AB26: =SUM(AB7:AB25) -> 640308 | AD26: Total (Pre-Vacancy) | AF26: =SUM(AF7:AF25) -> 72 | AG26: =+SUMPRODUCT(AG7:AG25,$AF7:$AF25) -> 59002 | AH26: =+SUMPRODUCT(AH7:AH25,$AF7:$AF25) -> 6335 | AI26: =SUM(AI7:AI25) -> 656580
B28: Year 2 | P28: =+$B28 -> Year 2 | W28: =+$B28 -> Year 2 | AD28: =+$B28 -> Year 2
B29: Unit Type | C29: AMI / S8 | D29: # of Units | E29: Avg. SF | F29: Avg. Utilities | G29: Avg. Max LITHC | H29: Net LIHTC | I29: Avg. Max FMR | J29: Net FMR | K29: =+K6 -> CoStar Rent | L29: Gross Rent | M29: Avg. Current Rent | N29: Yrly. Gross Income (Net Rent) | P29: Unit Type | Q29: AMI / S8 | R29: # of Units | S29: Avg. SF | T29: Avg. Utilities | U29: Max Current Vouchers | W29: Unit Type | X29: AMI / S8 | Y29: # of Units | Z29: Avg. SF | AA29: Avg. Utilities | AB29: Max NET LIHTC | AD29: Unit Type | AE29: AMI / S8 | AF29: # of Units | AG29: Avg. SF | AH29: Avg. Utilities | AI29: Max Current Vouchers + NET LIHTC
B30: =B7 -> 1x1 | C30: =C7 -> 50% AMI | D30: =$D7 -> 2 | E30: =E7 -> 701 | F30: =F7*(1+Dashboard!$P$12) -> 66.95 | G30: =G7*(1+Dashboard!$P$11) -> 670.53 | H30: =+G30-F30 -> 603.58 | I30: =I7*(1+Dashboard!$P$11) -> 703.49 | J30: =I30-F30 -> 636.54 | K30: =K7*(1+Dashboard!$P$11) -> 0 | L30: =M30+F30 -> 609.76 | M30: =M7*(1+Dashboard!$P$11) -> 542.81 | N30: =((M30*D30)*12) -> 13027.44 | P30: =B30 -> 1x1 | Q30: =C30 -> 50% AMI | R30: =D30 -> 2 | S30: =E30 -> 701 | T30: =F30 -> 66.95 | U30: =((M30*R30)*12) -> 13027.44 | W30: =B30 -> 1x1 | X30: =C30 -> 50% AMI | Y30: =D30 -> 2 | Z30: =E30 -> 701 | AA30: =F30 -> 66.95 | AB30: =((H30*Y30)*12) -> 14485.92 | AD30: =B30 -> 1x1 | AE30: =C30 -> 50% AMI | AF30: =D30 -> 2 | AG30: =E30 -> 701 | AH30: =F30 -> 66.95 | AI30: =+MAX(U30,AB30) -> 14485.92
B31: =B8 -> 1x1 | C31: =C8 -> 60% AMI | D31: =$D8 -> 0 | E31: =E8 -> 701 | F31: =F8*(1+Dashboard!$P$12) -> 66.95 | G31: =G8*(1+Dashboard!$P$11) -> 804.43 | H31: =+G31-F31 -> 737.48 | I31: =I8*(1+Dashboard!$P$11) -> 703.49 | J31: =I31-F31 -> 636.54 | K31: =K8*(1+Dashboard!$P$11) -> 0 | L31: =M31+F31 -> 66.95 | M31: =M8*(1+Dashboard!$P$11) -> 0 | N31: =((M31*D31)*12) -> 0 | P31: =B31 -> 1x1 | Q31: =C31 -> 60% AMI | R31: =D31 -> 0 | S31: =E31 -> 701 | T31: =F31 -> 66.95 | U31: =((M31*R31)*12) -> 0 | W31: =B31 -> 1x1 | X31: =C31 -> 60% AMI | Y31: =D31 -> 0 | Z31: =E31 -> 701 | AA31: =F31 -> 66.95 | AB31: =((H31*Y31)*12) -> 0 | AD31: =B31 -> 1x1 | AE31: =C31 -> 60% AMI | AF31: =D31 -> 0 | AG31: =E31 -> 701 | AH31: =F31 -> 66.95 | AI31: =+MAX(U31,AB31) -> 0
B32: =B9 -> 1x1 | C32: =C9 -> Market | D32: =$D9 -> 1 | E32: =E9 -> 701 | F32: =F9*(1+Dashboard!$P$12) -> 0 | G32: =G9*(1+Dashboard!$P$11) -> 0 | H32: =+G32-F32 -> 0 | I32: =I9*(1+Dashboard!$P$11) -> 703.49 | J32: =I32-F32 -> 703.49 | K32: =K9*(1+Dashboard!$P$11) -> 0 | L32: =M32+F32 -> 610.79 | M32: =M9*(1+Dashboard!$P$11) -> 610.79 | N32: =((M32*D32)*12) -> 7329.48 | P32: =B32 -> 1x1 | Q32: =C32 -> Market | R32: =D32 -> 1 | S32: =E32 -> 701 | T32: =F32 -> 0 | U32: =((M32*R32)*12) -> 7329.48 | W32: =B32 -> 1x1 | X32: =C32 -> Market | Y32: =D32 -> 1 | Z32: =E32 -> 701 | AA32: =F32 -> 0 | AB32: =((H32*Y32)*12) -> 0 | AD32: =B32 -> 1x1 | AE32: =C32 -> Market | AF32: =D32 -> 1 | AG32: =E32 -> 701 | AH32: =F32 -> 0 | AI32: =+MAX(U32,AB32) -> 7329.48
B33: =B10 -> 1x1 | C33: =C10 -> S8 Voucher | D33: =$D10 -> 3 | E33: =E10 -> 701 | F33: =F10*(1+Dashboard!$P$12) -> 66.95 | G33: =G10*(1+Dashboard!$P$11) -> 804.43 | H33: =+G33-F33 -> 737.48 | I33: =I10*(1+Dashboard!$P$11) -> 703.49 | J33: =I33-F33 -> 636.54 | K33: =K10*(1+Dashboard!$P$11) -> 0 | L33: =M33+F33 -> 605.64 | M33: =M10*(1+Dashboard!$P$11) -> 538.69 | N33: =((M33*D33)*12) -> 19392.84 | P33: =B33 -> 1x1 | Q33: =C33 -> S8 Voucher | R33: =D33 -> 3 | S33: =E33 -> 701 | T33: =F33 -> 66.95 | U33: =((M33*R33)*12) -> 19392.84 | W33: =B33 -> 1x1 | X33: =C33 -> S8 Voucher | Y33: =D33 -> 3 | Z33: =E33 -> 701 | AA33: =F33 -> 66.95 | AB33: =((H33*Y33)*12) -> 26549.28 | AD33: =B33 -> 1x1 | AE33: =C33 -> S8 Voucher | AF33: =D33 -> 3 | AG33: =E33 -> 701 | AH33: =F33 -> 66.95 | AI33: =+MAX(U33,AB33) -> 26549.28
B34: =B11 -> 2x1.5 | C34: =C11 -> 40% AMI | D34: =$D11 -> 1 | E34: =E11 -> 940 | F34: =F11*(1+Dashboard!$P$12) -> 88.58 | G34: =G11*(1+Dashboard!$P$11) -> 555.17 | H34: =+G34-F34 -> 466.59 | I34: =I11*(1+Dashboard!$P$11) -> 801.34 | J34: =I34-F34 -> 712.76 | K34: =K11*(1+Dashboard!$P$11) -> 0 | L34: =M34+F34 -> 567.53 | M34: =M11*(1+Dashboard!$P$11) -> 478.95 | N34: =((M34*D34)*12) -> 5747.4 | P34: =B34 -> 2x1.5 | Q34: =C34 -> 40% AMI | R34: =D34 -> 1 | S34: =E34 -> 940 | T34: =F34 -> 88.58 | U34: =((M34*R34)*12) -> 5747.4 | W34: =B34 -> 2x1.5 | X34: =C34 -> 40% AMI | Y34: =D34 -> 1 | Z34: =E34 -> 940 | AA34: =F34 -> 88.58 | AB34: =((H34*Y34)*12) -> 5599.08 | AD34: =B34 -> 2x1.5 | AE34: =C34 -> 40% AMI | AF34: =D34 -> 1 | AG34: =E34 -> 940 | AH34: =F34 -> 88.58 | AI34: =+MAX(U34,AB34) -> 5747.4
B35: =B12 -> 2x1.5 | C35: =C12 -> 50% AMI | D35: =$D12 -> 3 | E35: =E12 -> 990 | F35: =F12*(1+Dashboard!$P$12) -> 88.58 | G35: =G12*(1+Dashboard!$P$11) -> 715.85 | H35: =+G35-F35 -> 627.27 | I35: =I12*(1+Dashboard!$P$11) -> 801.34 | J35: =I35-F35 -> 712.76 | K35: =K12*(1+Dashboard!$P$11) -> 0 | L35: =M35+F35 -> 685.98 | M35: =M12*(1+Dashboard!$P$11) -> 597.4 | N35: =((M35*D35)*12) -> 21506.4 | P35: =B35 -> 2x1.5 | Q35: =C35 -> 50% AMI | R35: =D35 -> 3 | S35: =E35 -> 990 | T35: =F35 -> 88.58 | U35: =((M35*R35)*12) -> 21506.4 | W35: =B35 -> 2x1.5 | X35: =C35 -> 50% AMI | Y35: =D35 -> 3 | Z35: =E35 -> 990 | AA35: =F35 -> 88.58 | AB35: =((H35*Y35)*12) -> 22581.72 | AD35: =B35 -> 2x1.5 | AE35: =C35 -> 50% AMI | AF35: =D35 -> 3 | AG35: =E35 -> 990 | AH35: =F35 -> 88.58 | AI35: =+MAX(U35,AB35) -> 22581.72
B36: =B13 -> 2x1.5 | C36: =C13 -> 60% AMI | D36: =$D13 -> 2 | E36: =E13 -> 980 | F36: =F13*(1+Dashboard!$P$12) -> 88.58 | G36: =G13*(1+Dashboard!$P$11) -> 876.53 | H36: =+G36-F36 -> 787.95 | I36: =I13*(1+Dashboard!$P$11) -> 801.34 | J36: =I36-F36 -> 712.76 | K36: =K13*(1+Dashboard!$P$11) -> 0 | L36: =M36+F36 -> 749.84 | M36: =M13*(1+Dashboard!$P$11) -> 661.26 | N36: =((M36*D36)*12) -> 15870.24 | P36: =B36 -> 2x1.5 | Q36: =C36 -> 60% AMI | R36: =D36 -> 2 | S36: =E36 -> 980 | T36: =F36 -> 88.58 | U36: =((M36*R36)*12) -> 15870.24 | W36: =B36 -> 2x1.5 | X36: =C36 -> 60% AMI | Y36: =D36 -> 2 | Z36: =E36 -> 980 | AA36: =F36 -> 88.58 | AB36: =((H36*Y36)*12) -> 18910.8 | AD36: =B36 -> 2x1.5 | AE36: =C36 -> 60% AMI | AF36: =D36 -> 2 | AG36: =E36 -> 980 | AH36: =F36 -> 88.58 | AI36: =+MAX(U36,AB36) -> 18910.8
B37: =B14 -> 2x2 | C37: =C14 -> 50% AMI | D37: =$D14 -> 1 | E37: =E14 -> 968 | F37: =F14*(1+Dashboard!$P$12) -> 88.58 | G37: =G14*(1+Dashboard!$P$11) -> 715.85 | H37: =+G37-F37 -> 627.27 | I37: =I14*(1+Dashboard!$P$11) -> 801.34 | J37: =I37-F37 -> 712.76 | K37: =K14*(1+Dashboard!$P$11) -> 0 | L37: =M37+F37 -> 716.88 | M37: =M14*(1+Dashboard!$P$11) -> 628.3 | N37: =((M37*D37)*12) -> 7539.6 | P37: =B37 -> 2x2 | Q37: =C37 -> 50% AMI | R37: =D37 -> 1 | S37: =E37 -> 968 | T37: =F37 -> 88.58 | U37: =((M37*R37)*12) -> 7539.6 | W37: =B37 -> 2x2 | X37: =C37 -> 50% AMI | Y37: =D37 -> 1 | Z37: =E37 -> 968 | AA37: =F37 -> 88.58 | AB37: =((H37*Y37)*12) -> 7527.24 | AD37: =B37 -> 2x2 | AE37: =C37 -> 50% AMI | AF37: =D37 -> 1 | AG37: =E37 -> 968 | AH37: =F37 -> 88.58 | AI37: =+MAX(U37,AB37) -> 7539.6
B38: =B15 -> 2x2 | C38: =C15 -> 60% AMI | D38: =$D15 -> 2 | E38: =E15 -> 968 | F38: =F15*(1+Dashboard!$P$12) -> 88.58 | G38: =G15*(1+Dashboard!$P$11) -> 876.53 | H38: =+G38-F38 -> 787.95 | I38: =I15*(1+Dashboard!$P$11) -> 801.34 | J38: =I38-F38 -> 712.76 | K38: =K15*(1+Dashboard!$P$11) -> 0 | L38: =M38+F38 -> 742.63 | M38: =M15*(1+Dashboard!$P$11) -> 654.05 | N38: =((M38*D38)*12) -> 15697.2 | P38: =B38 -> 2x2 | Q38: =C38 -> 60% AMI | R38: =D38 -> 2 | S38: =E38 -> 968 | T38: =F38 -> 88.58 | U38: =((M38*R38)*12) -> 15697.2 | W38: =B38 -> 2x2 | X38: =C38 -> 60% AMI | Y38: =D38 -> 2 | Z38: =E38 -> 968 | AA38: =F38 -> 88.58 | AB38: =((H38*Y38)*12) -> 18910.8 | AD38: =B38 -> 2x2 | AE38: =C38 -> 60% AMI | AF38: =D38 -> 2 | AG38: =E38 -> 968 | AH38: =F38 -> 88.58 | AI38: =+MAX(U38,AB38) -> 18910.8
B39: =B16 -> 2x2 | C39: =C16 -> Market | D39: =$D16 -> 0 | E39: =E16 -> 968 | F39: =F16*(1+Dashboard!$P$12) -> 0 | G39: =G16*(1+Dashboard!$P$11) -> 0 | H39: =+G39-F39 -> 0 | I39: =I16*(1+Dashboard!$P$11) -> 801.34 | J39: =I39-F39 -> 801.34 | K39: =K16*(1+Dashboard!$P$11) -> 0 | L39: =M39+F39 -> 0 | M39: =M16*(1+Dashboard!$P$11) -> 0 | N39: =((M39*D39)*12) -> 0 | P39: =B39 -> 2x2 | Q39: =C39 -> Market | R39: =D39 -> 0 | S39: =E39 -> 968 | T39: =F39 -> 0 | U39: =((M39*R39)*12) -> 0 | W39: =B39 -> 2x2 | X39: =C39 -> Market | Y39: =D39 -> 0 | Z39: =E39 -> 968 | AA39: =F39 -> 0 | AB39: =((H39*Y39)*12) -> 0 | AD39: =B39 -> 2x2 | AE39: =C39 -> Market | AF39: =D39 -> 0 | AG39: =E39 -> 968 | AH39: =F39 -> 0 | AI39: =+MAX(U39,AB39) -> 0
B40: =B17 -> 2x2 (TH) | C40: =C17 -> 40% AMI | D40: =$D17 -> 1 | E40: =E17 -> 1058 | F40: =F17*(1+Dashboard!$P$12) -> 88.58 | G40: =G17*(1+Dashboard!$P$11) -> 555.17 | H40: =+G40-F40 -> 466.59 | I40: =I17*(1+Dashboard!$P$11) -> 801.34 | J40: =I40-F40 -> 712.76 | K40: =K17*(1+Dashboard!$P$11) -> 0 | L40: =M40+F40 -> 552.08 | M40: =M17*(1+Dashboard!$P$11) -> 463.5 | N40: =((M40*D40)*12) -> 5562 | P40: =B40 -> 2x2 (TH) | Q40: =C40 -> 40% AMI | R40: =D40 -> 1 | S40: =E40 -> 1058 | T40: =F40 -> 88.58 | U40: =((M40*R40)*12) -> 5562 | W40: =B40 -> 2x2 (TH) | X40: =C40 -> 40% AMI | Y40: =D40 -> 1 | Z40: =E40 -> 1058 | AA40: =F40 -> 88.58 | AB40: =((H40*Y40)*12) -> 5599.08 | AD40: =B40 -> 2x2 (TH) | AE40: =C40 -> 40% AMI | AF40: =D40 -> 1 | AG40: =E40 -> 1058 | AH40: =F40 -> 88.58 | AI40: =+MAX(U40,AB40) -> 5599.08
B41: =B18 -> 2x2 (TH) | C41: =C18 -> 50% AMI | D41: =$D18 -> 1 | E41: =E18 -> 1058 | F41: =F18*(1+Dashboard!$P$12) -> 88.58 | G41: =G18*(1+Dashboard!$P$11) -> 715.85 | H41: =+G41-F41 -> 627.27 | I41: =I18*(1+Dashboard!$P$11) -> 801.34 | J41: =I41-F41 -> 712.76 | K41: =K18*(1+Dashboard!$P$11) -> 0 | L41: =M41+F41 -> 150.38 | M41: =M18*(1+Dashboard!$P$11) -> 61.8 | N41: =((M41*D41)*12) -> 741.6 | P41: =B41 -> 2x2 (TH) | Q41: =C41 -> 50% AMI | R41: =D41 -> 1 | S41: =E41 -> 1058 | T41: =F41 -> 88.58 | U41: =((M41*R41)*12) -> 741.6 | W41: =B41 -> 2x2 (TH) | X41: =C41 -> 50% AMI | Y41: =D41 -> 1 | Z41: =E41 -> 1058 | AA41: =F41 -> 88.58 | AB41: =((H41*Y41)*12) -> 7527.24 | AD41: =B41 -> 2x2 (TH) | AE41: =C41 -> 50% AMI | AF41: =D41 -> 1 | AG41: =E41 -> 1058 | AH41: =F41 -> 88.58 | AI41: =+MAX(U41,AB41) -> 7527.24
... B48: =B25 -> 3x2 (TH) | C48: =C25 -> S8 Voucher | D48: =$D25 -> 11 | E48: =E25 -> 1296 | F48: =F25*(1+Dashboard!$P$12) -> 110.21 | G48: =G25*(1+Dashboard!$P$11) -> 1005.28 | H48: =+G48-F48 -> 895.07 | I48: =I25*(1+Dashboard!$P$11) -> 1053.69 | J48: =I48-F48 -> 943.48 | K48: =K25*(1+Dashboard!$P$11) -> 0 | L48: =M48+F48 -> 963.05 | M48: =M25*(1+Dashboard!$P$11) -> 852.84 | N48: =((M48*D48)*12) -> 112574.88 | P48: =B48 -> 3x2 (TH) | Q48: =C48 -> S8 Voucher | R48: =D48 -> 11 | S48: =E48 -> 1296 | T48: =F48 -> 110.21 | U48: =((M48*R48)*12) -> 112574.88 | W48: =B48 -> 3x2 (TH) | X48: =C48 -> S8 Voucher | Y48: =D48 -> 11 | Z48: =E48 -> 1296 | AA48: =F48 -> 110.21 | AB48: =((H48*Y48)*12) -> 118149.24 | AD48: =B48 -> 3x2 (TH) | AE48: =C48 -> S8 Voucher | AF48: =D48 -> 11 | AG48: =E48 -> 1296 | AH48: =F48 -> 110.21 | AI48: =+MAX(U48,AB48) -> 118149.24
